Workbook
Name _77: RAPORT!$F$6

Sheet DATA
A1: SESUAIKAN NAMA GURU NIP, KEP SEK NIP,SISWA DAN KKM
B2: Guru Mapel | D2: Kepala Sekolah | F2: KKM
B3: KASMIN, S.Pd | D3: Dra. BAROKAH GUNIARTI
B4: NIP : 196609141990031007 | D4: NIP : 196901081996122004 | F4: 80
A7: DAFTAR NAMA SISWA
B8: 9A | D8: 9B | F8: 9C | H8: 9D | J8: 9E | L8: 9F
A10: 1 | B10: Affan Bagus Ramadhani | C10: 1 | D10: Abid Lionel Abdillah | E10: 1 | F10: Ahmad Husain | G10: 1 | H10: Aditya Wahyu Putra Septiadi | I10: 1 | J10: Adyatma Danendra Abimanyu | K10: 1 | L10: Ahmad Azam Muhanif
A11: 2 | B11: Affansa Rayya Assalafi | C11: 2 | D11: Aditria Bintang Mustofa | E11: 2 | F11: Albeth Christian F. | G11: 2 | H11: Al Fuzu Daya Satria | I11: 2 | J11: Ainaya Aprillia Azzahra | K11: 2 | L11: Ananda Rafa Mahesa Putra
A12: 3 | B12: Agel Fransiska | C12: 3 | D12: Agni Wulan Pramesti | E12: 3 | F12: Alfino Kurniawan | G12: 3 | H12: Amanda Kirana Maharani | I12: 3 | J12: Alvicko Aprellio Jordan | K12: 3 | L12: Aprian Caysa Raditiansyah
A13: 4 | B13: Alfin Putra Firmansyah | C13: 4 | D13: Ahmad Irfan Annadif | E13: 4 | F13: Alif Jalu Adil | G13: 4 | H13: Andra Prima Reza | I13: 4 | J13: Anastain | K13: 4 | L13: Attaya Nadine Vanessa
A14: 5 | B14: Almira Sadia Qonitah | C14: 5 | D14: Alesha Najwa Adelia | E14: 5 | F14: Almira Tian Az Zahra | G14: 5 | H14: Ayu Safitri Intan Zahwa | I14: 5 | J14: Angginia Regina Putri | K14: 5 | L14: Dimas Suryo Admodjo
A15: 6 | B15: Arif Perdana Putra | C15: 6 | D15: Ana Kharisma Wardani | E15: 6 | F15: Alvino Dafa Radhwa Aqilah | G15: 6 | H15: Azzahra Quinnsha Setyana | I15: 6 | J15: Arfan Faqih Al Hikam | K15: 6 | L15: Dwi Erinadestari
A16: 7 | B16: Asifa Nariyati | C16: 7 | D16: Angga Rizki Satriya Utama | E16: 7 | F16: Ananda Dhanis Syarifudien | G16: 7 | H16: Bryan Marcanda | I16: 7 | J16: Bilqis Aura Dayinta | K16: 7 | L16: Eka Yuanita Safa
A17: 8 | B17: Calvin Mandala Putra | C17: 8 | D17: Ardiyan Vebri Pratama | E17: 8 | F17: Andra Putra Wahyu Baskara | G17: 8 | H17: Chelsea Felita Matiune | I17: 8 | J17: Chayril Arya Saputra | K17: 8 | L17: Ellisa Adelia Putri
A18: 9 | B18: Decha Rifqoh Alma Dhini | C18: 9 | D18: Aurel Azza Adellia Putri | E18: 9 | F18: Ardhan Restu Pratama | G18: 9 | H18: Dharma Tegar Sathrya | I18: 9 | J18: Dinda Cahya Kirana | K18: 9 | L18: Elsa Adinda Putri
A19: 10 | B19: Fathir Hibatullah Harahap | C19: 10 | D19: Darasti Keyshafa Azumi | E19: 10 | F19: Ardi Setyo Nugroho | G19: 10 | H19: Eza Septian Dinata | I19: 10 | J19: Farhan Safiy Devangga | K19: 10 | L19: Erick Putra Wijaya
A20: 11 | B20: Gendhis Putri Ayreanti | C20: 11 | D20: Dea Resti Lian Dana Sari | E20: 11 | F20: Az Zahra Aulia Rahma | G20: 11 | H20: Hadi Khoirul Anwar | I20: 11 | J20: Herlin Eka Noviana | K20: 11 | L20: Intan Qurrota A'Yun
A21: 12 | B21: Habibi Lazuardi | C21: 12 | D21: Desta Dwi Lestari | E21: 12 | F21: Desti Dwi Wahyuni | G21: 12 | H21: Ica Nur Setyo Anugrah | I21: 12 | J21: Irfan Al Khafidz | K21: 12 | L21: Johan Renaldi
... A39: 30 | B39: Sila Ayu Kurnia | C39: 30 | D39: Syauqi Lazuardi | E39: 30 | F39: Roxy Lantip Afpriba | G39: 30 | H39: Zahfa Zilvilya Putri | I39: 30 | J39: Yanuar Putra Akbar | K39: 30 | L39: Vega Olivia Ramandhani
A40: 31 | B40: Sindhi Nandha Lusia | C40: 31 | D40: Zakya Ninu Azzahra | E40: 31 | F40: Syifa Maulida Zahra | G40: 31 | H40: Zaidan Rafa Prawidi | I40: 31 | K40: 31
A41: 32 | B41: Siti Alfiani | C41: 32 | D41: Zivara Layly Amaratungga | E41: 32 | F41: Virna Meisya Amelia | G41: 32 | I41: 32 | K41: 32
A42: 33 | C42: 33 | E42: 33 | F42: - | G42: 33 | I42: 33 | K42: 33
A43: 34 | C43: 34 | E43: 34 | F43: - | G43: 34 | I43: 34 | K43: 34
A46: URUT DAPODIK
A48: 1 | B48: ARINA ROEIHATUL JINAN | C48: 1 | D48: ADELIA KURNIA AJENG | E48: 1 | F48: AHMAD NASRULLAH | G48: 1 | H48: Adinaya Nurma Isfarahanum | I48: 1 | J48: ACHMAD YUDISTIRA ADI NUGROHO | K48: 1 | L48: AKHMAD SIDIQ MUBAROK
A49: 2 | B49: BIAS IFFAH AMALIYAH PUTRI | C49: 2 | D49: AISYAH NURUL KHASANAH | E49: 2 | F49: ALDIKA ADITYA PRASTYO | G49: 2 | H49: AGENG CAHYA PERMADI | I49: 2 | J49: Alfianti Agustin | K49: 2 | L49: ANANTA GITA SAPUTRA
A50: 3 | B50: DAFA ARIEF SAPUTRA | C50: 3 | D50: ALYA NAJZMA AFI RAMADHANI | E50: 3 | F50: ALDY NUHGROHO | G50: 3 | H50: ANDRIAN HANUNG SAPUTRA | I50: 3 | J50: AMANDA RISFI AYU FEBRIYANTI | K50: 3 | L50: Angelica Gracea Putri
A51: 4 | B51: DANTIKIANI LU'LU'UL JANNAH | C51: 4 | D51: ANANDA MEYLINA | E51: 4 | F51: APRIAN WISNU ADITYAWAN | G51: 4 | H51: AULYA NUR ISTIQOMAH | I51: 4 | J51: ANDREAN RESTU SUGIONO | K51: 4 | L51: ARSHAVIN PUTERA PRASETYO
A52: 5 | B52: DESTHA ALVAZYA | C52: 5 | D52: ANGGIT PUJI HERNITHA | E52: 5 | F52: AVIV WIDI PRATAMA | G52: 5 | H52: CHATERIN DEBORA HANA IVANOVIC | I52: 5 | J52: ASRORIYADI | K52: 5 | L52: ARVINA ANGELIA ANATASYA
A53: 6 | B53: FADHIL PUTRA LESMANA | C53: 6 | D53: ARISFA NAYSILA | E53: 6 | F53: DAVA ISRA RIAWAN | G53: 6 | H53: Daiva Ezar Ardiyanta Hastama | I53: 6 | J53: DANANG ARIS SANJAYA | K53: 6 | L53: AYUDYA NURUL IVA
A54: 7 | B54: Farid Azhar Kurniawan | C54: 7 | D54: ARIYA DHANI SAPUTRA | E54: 7 | F54: DEVITA RIZKY NATASYA | G54: 7 | H54: Dhayen Satya Raka Dikta | I54: 7 | J54: DHIFA RIZQI FEBRIAN | K54: 7 | L54: AZZAHRA PRASETYANINGSIH
A55: 8 | B55: FATIMATUZ ZAHRO | C55: 8 | D55: Azzera Hafiza Sachnas | E55: 8 | F55: DEWISTA AYU TIARA CAHAYANI | G55: 8 | H55: DINDA MEISYA AYU PUTRI | I55: 8 | J55: DIKI CANDRA STIAWAN | K55: 8 | L55: CHIKA MEILA KINANTI
A56: 9 | B56: FIRMAN ZAKARIYA | C56: 9 | D56: BAGAS ALGIAN NATA | E56: 9 | F56: DIKA RAHMAT DANI | G56: 9 | H56: DWI LESTARI | I56: 9 | J56: ERLANGGA SETIAWAN | K56: 9 | L56: CHUSNYNDA INDAH PRATIWI
A57: 10 | B57: FRISKA PRADITA FEBRIYANI | C57: 10 | D57: Damar Alviansyah | E57: 10 | F57: Dita Sekarwati | G57: 10 | H57: ZAKI KELUAR | I57: 10 | J57: FADIL ALI UMAR | K57: 10 | L57: DIMAS ARVIAN SAPUTRA
A58: 11 | B58: GANANG PAMUNGKAS | C58: 11 | D58: DEWA AYU KETUT SAFIAH SALMA | E58: 11 | F58: ELIDA SAZKIA APRIANY | G58: 11 | H58: FADHLI RIJAL | I58: 11 | J58: FANO ANDRIYANTO | K58: 11 | L58: DONA AURELLIA HARYANI
A59: 12 | B59: GANESWARA LINTANG DHAMARJATI | C59: 12 | D59: Dwi Arum Melati | E59: 12 | F59: Elsa Setyo Mangesthi | G59: 12 | H59: Feni Fefi Apriliya | I59: 12 | J59: GENDIS WORO PRAMESTI | K59: 12 | L59: FIRGA DWI RAMADHAN
... A77: 30 | B77: SYAFIQ KHOIRUL AZZAM | C77: 30 | D77: WILDAN NAILUN NIAM | E77: 30 | F77: VIEVIEANE PUJI ASTUTI | G77: 30 | H77: TYA NUR AISYAH | I77: 30 | J77: SHERLY EMILIANA PUTRI | K77: 30 | L77: ULIN NUHA AWALUDIN
A78: 31 | B78: VANESIA NADILA PRAMESTI | C78: 31 | D78: YOVAN PUTRA ANANDA | E78: 31 | F78: YOVIE AGMAR PRASETYA | G78: 31 | H78: VANESSA ANGELINA LOOGIKA PUTRI | I78: 31 | J78: SISKA RAMADHANI | K78: 31
A79: 32 | B79: VE NAFISAH AZZAHRA | C79: 32 | D79: ZUNIA ARTHA SILVANA | E79: 32 | F79: ZEFANA EFELYN AVENA | G79: 32 | H79: VHENDO NOVRIENI SAKTI GUMILANG | I79: 32 | J79: UMI SHABRINA RAHMAWATI | K79: 32
A82: 1 | B82: =IF(B48=B10,"SAMA","TDK SAMA") -> TDK SAMA | C82: 1 | D82: =IF(D48=D10,"SAMA","TDK SAMA") -> TDK SAMA | E82: 1 | F82: =IF(F48=F10,"SAMA","TDK SAMA") -> TDK SAMA | G82: 1 | H82: =IF(H48=H10,"SAMA","TDK SAMA") -> TDK SAMA | I82: 1 | J82: =IF(J48=J10,"SAMA","TDK SAMA") -> TDK SAMA | K82: 1 | L82: =IF(L48=L10,"SAMA","TDK SAMA") -> TDK SAMA
...

Sheet UH1
A1: ANALISA HASIL PH MATEMATIKA KLS IX SMT GENAP | Q1: PROGRAM DAN PELAKSANAAN
A2: SMP I LIMBANGAN TH 2025/2026 | Q2: PERBAIKAN / PENGAYAAN
A4: KLS | C4: =DATA!B8 -> 9A | D4: PH ke : | F4: 1 | I4: Tanggal : | K4: 45877 | M4: SK no : | N4: =F4 -> 1 | Q4: Waktu pelaksanaan : | R4: =K4+7 -> 45884
C5: No Soal | D5: 1 | E5: 2 | F5: 3 | G5: 4 | H5: 5 | I5: JUM | J5: % | K5: KETUN | L5: NILAI | M5: KETERANGAN | R5: HASIL
A6: NO | B6: NIS | C6: Scor | D6: 30 | E6: 40 | F6: 30 | I6: =SUM(D6:H6) -> 100 | J6: Keter | K6: TASAN | L6: SETLH | Q6: NAMA | R6: PERBK | S6: URAIAN PROGRAM
C7: NAMA | J7: capaian | L7: PERBKN | R7: PGYAAN
A8: 1 | C8: =DATA!B10 -> Affan Bagus Ramadhani | D8: 10 | I8: =SUM(D8:H8) -> 10 | J8: =I8 -> 10 | K8: =IF(J8<$N$10,"tdk tuntas","tuntas") -> tdk tuntas | L8: =IF(J8<=39.9,"80",IF(J8<=59.9,"81",IF(J8<=69.9,"82",IF(J8<=74.9,"83",IF(J8<=78.9,"84",IF(J8<=78.9,"85",IF(J8>=78.9,J8," "))))))) -> 80 | Q8: =C8 -> Affan Bagus Ramadhani | R8: =IF(I8<$N$10,"80","") -> 80
A9: 2 | C9: =DATA!B11 -> Affansa Rayya Assalafi | D9: 20 | I9: =SUM(D9:H9) -> 20 | J9: =I9 -> 20 | K9: =IF(J9<$N$10,"tdk tuntas","tuntas") -> tdk tuntas | L9: =IF(J9<=39.9,"80",IF(J9<=59.9,"81",IF(J9<=69.9,"82",IF(J9<=74.9,"83",IF(J9<=78.9,"84",IF(J9<=78.9,"85",IF(J9>=78.9,J9," "))))))) -> 80 | Q9: =C9 -> Affansa Rayya Assalafi | R9: =IF(I9<$N$10,"81","") -> 81 | S9: PERBAIKAN
A10: 3 | C10: =DATA!B12 -> Agel Fransiska | D10: 50 | I10: =SUM(D10:H10) -> 50 | J10: =I10 -> 50 | K10: =IF(J10<$N$10,"tdk tuntas","tuntas") -> tdk tuntas | L10: =IF(J10<=39.9,"80",IF(J10<=59.9,"81",IF(J10<=69.9,"82",IF(J10<=74.9,"83",IF(J10<=78.9,"84",IF(J10<=78.9,"85",IF(J10>=78.9,J10," "))))))) -> 81 | M10: KKM | N10: =DATA!F4 -> 80 | Q10: =C10 -> Agel Fransiska | R10: =IF(I10<$N$10,"81","") -> 81
A11: 4 | C11: =DATA!B13 -> Alfin Putra Firmansyah | D11: 60 | I11: =SUM(D11:H11) -> 60 | J11: =I11 -> 60 | K11: =IF(J11<$N$10,"tdk tuntas","tuntas") -> tdk tuntas | L11: =IF(J11<=39.9,"80",IF(J11<=59.9,"81",IF(J11<=69.9,"82",IF(J11<=74.9,"83",IF(J11<=78.9,"84",IF(J11<=78.9,"85",IF(J11>=78.9,J11," "))))))) -> 82 | Q11: =C11 -> Alfin Putra Firmansyah | R11: =IF(I11<$N$10,"84","") -> 84 | T11: Membuat rangkuman
A12: 5 | C12: =DATA!B14 -> Almira Sadia Qonitah | D12: 80 | I12: =SUM(D12:H12) -> 80 | J12: =I12 -> 80 | K12: =IF(J12<$N$10,"tdk tuntas","tuntas") -> tuntas | L12: =IF(J12<=39.9,"80",IF(J12<=59.9,"81",IF(J12<=69.9,"82",IF(J12<=74.9,"83",IF(J12<=78.9,"84",IF(J12<=78.9,"85",IF(J12>=78.9,J12," "))))))) -> 80 | Q12: =C12 -> Almira Sadia Qonitah | R12: =IF(I12<$N$10,"87","") | T12: Menbuat soal
A13: 6 | C13: =DATA!B15 -> Arif Perdana Putra | D13: 0 | I13: =SUM(D13:H13) -> 0 | J13: =I13 -> 0 | K13: =IF(J13<$N$10,"tdk tuntas","tuntas") -> tdk tuntas | L13: =IF(J13<=39.9,"80",IF(J13<=59.9,"81",IF(J13<=69.9,"82",IF(J13<=74.9,"83",IF(J13<=78.9,"84",IF(J13<=78.9,"85",IF(J13>=78.9,J13," "))))))) -> 80 | M13: Hasil Analisa | Q13: =C13 -> Arif Perdana Putra | R13: =IF(I13<$N$10,"82","") -> 82 | T13: dan penyelesaiannya
A14: 7 | C14: =DATA!B16 -> Asifa Nariyati | D14: 30 | I14: =SUM(D14:H14) -> 30 | J14: =I14 -> 30 | K14: =IF(J14<$N$10,"tdk tuntas","tuntas") -> tdk tuntas | L14: =IF(J14<=39.9,"80",IF(J14<=59.9,"81",IF(J14<=69.9,"82",IF(J14<=74.9,"83",IF(J14<=78.9,"84",IF(J14<=78.9,"85",IF(J14>=78.9,J14," "))))))) -> 80 | Q14: =C14 -> Asifa Nariyati | R14: =IF(I14<$N$10,"80","") -> 80 | S14: V | T14: Mengerjakan soal
A15: 8 | C15: =DATA!B17 -> Calvin Mandala Putra | D15: 30 | I15: =SUM(D15:H15) -> 30 | J15: =I15 -> 30 | K15: =IF(J15<$N$10,"tdk tuntas","tuntas") -> tdk tuntas | L15: =IF(J15<=39.9,"80",IF(J15<=59.9,"81",IF(J15<=69.9,"82",IF(J15<=74.9,"83",IF(J15<=78.9,"84",IF(J15<=78.9,"85",IF(J15>=78.9,J15," "))))))) -> 80 | M15: a. Tuntas Klasikal | Q15: =C15 -> Calvin Mandala Putra | R15: =IF(I15<$N$10,"84","") -> 84 | T15: dengan bobot sama
A16: 9 | C16: =DATA!B18 -> Decha Rifqoh Alma Dhini | D16: 30 | I16: =SUM(D16:H16) -> 30 | J16: =I16 -> 30 | K16: =IF(J16<$N$10,"tdk tuntas","tuntas") -> tdk tuntas | L16: =IF(J16<=39.9,"80",IF(J16<=59.9,"81",IF(J16<=69.9,"82",IF(J16<=74.9,"83",IF(J16<=78.9,"84",IF(J16<=78.9,"85",IF(J16>=78.9,J16," "))))))) -> 80 | Q16: =C16 -> Decha Rifqoh Alma Dhini | R16: =IF(I16<$N$10,"88","") -> 88
A17: 10 | C17: =DATA!B19 -> Fathir Hibatullah Harahap | D17: 0 | I17: =SUM(D17:H17) -> 0 | J17: =I17 -> 0 | K17: =IF(J17<$N$10,"tdk tuntas","tuntas") -> tdk tuntas | L17: =IF(J17<=39.9,"80",IF(J17<=59.9,"81",IF(J17<=69.9,"82",IF(J17<=74.9,"83",IF(J17<=78.9,"84",IF(J17<=78.9,"85",IF(J17>=78.9,J17," "))))))) -> 80 | Q17: =C17 -> Fathir Hibatullah Harahap | R17: =IF(I17<$N$10,"85","") -> 85 | S17: PENGAYAAN
A18: 11 | C18: =DATA!B20 -> Gendhis Putri Ayreanti | D18: 40 | I18: =SUM(D18:H18) -> 40 | J18: =I18 -> 40 | K18: =IF(J18<$N$10,"tdk tuntas","tuntas") -> tdk tuntas | L18: =IF(J18<=39.9,"80",IF(J18<=59.9,"81",IF(J18<=69.9,"82",IF(J18<=74.9,"83",IF(J18<=78.9,"84",IF(J18<=78.9,"85",IF(J18>=78.9,J18," "))))))) -> 81 | Q18: =C18 -> Gendhis Putri Ayreanti | R18: =IF(I18<$N$10,"85","") -> 85
A19: 12 | C19: =DATA!B21 -> Habibi Lazuardi | D19: 90 | I19: =SUM(D19:H19) -> 90 | J19: =I19 -> 90 | K19: =IF(J19<$N$10,"tdk tuntas","tuntas") -> tuntas | L19: =IF(J19<=39.9,"80",IF(J19<=59.9,"81",IF(J19<=69.9,"82",IF(J19<=74.9,"83",IF(J19<=78.9,"84",IF(J19<=78.9,"85",IF(J19>=78.9,J19," "))))))) -> 90 | M19: Banyak siswa seluruhnya | N19: =K46 -> 32 | Q19: =C19 -> Habibi Lazuardi | R19: =IF(I19<$N$10,"85","") | S19: V | T19: Menyelesaikan soal soal
A20: 13 | C20: =DATA!B22 -> Herina Sasha Rasati | D20: 0 | I20: =SUM(D20:H20) -> 0 | J20: =I20 -> 0 | K20: =IF(J20<$N$10,"tdk tuntas","tuntas") -> tdk tuntas | L20: =IF(J20<=39.9,"80",IF(J20<=59.9,"81",IF(J20<=69.9,"82",IF(J20<=74.9,"83",IF(J20<=78.9,"84",IF(J20<=78.9,"85",IF(J20>=78.9,J20," "))))))) -> 80 | M20: Banyak siswa yg tuntas | N20: =K44 -> 8 | Q20: =C20 -> Herina Sasha Rasati | R20: =IF(I20<$N$10,"85","") -> 85 | T20: pengayaan
A21: 14 | C21: =DATA!B23 -> Ivan Adi Saputra | D21: 10 | I21: =SUM(D21:H21) -> 10 | J21: =I21 -> 10 | K21: =IF(J21<$N$10,"tdk tuntas","tuntas") -> tdk tuntas | L21: =IF(J21<=39.9,"80",IF(J21<=59.9,"81",IF(J21<=69.9,"82",IF(J21<=74.9,"83",IF(J21<=78.9,"84",IF(J21<=78.9,"85",IF(J21>=78.9,J21," "))))))) -> 80 | M21: Prosentase ketuntasan | N21: =N20/N19*100 -> 25 | O21: % | Q21: =C21 -> Ivan Adi Saputra | R21: =IF(I21<$N$10,"85","") -> 85 | T21: Mempelajari materi / KD
A22: 15 | C22: =DATA!B24 -> Ivander Veda Ardyanta | D22: 90 | I22: =SUM(D22:H22) -> 90 | J22: =I22 -> 90 | K22: =IF(J22<$N$10,"tdk tuntas","tuntas") -> tuntas | L22: =IF(J22<=39.9,"80",IF(J22<=59.9,"81",IF(J22<=69.9,"82",IF(J22<=74.9,"83",IF(J22<=78.9,"84",IF(J22<=78.9,"85",IF(J22>=78.9,J22," "))))))) -> 90 | Q22: =C22 -> Ivander Veda Ardyanta | R22: =IF(I22<$N$10,"85","") | T22: berikutnya
A23: 16 | C23: =DATA!B25 -> Keysa Lutfi Yana Putri | D23: 0 | I23: =SUM(D23:H23) -> 0 | J23: =I23 -> 0 | K23: =IF(J23<$N$10,"tdk tuntas","tuntas") -> tdk tuntas | L23: =IF(J23<=39.9,"80",IF(J23<=59.9,"81",IF(J23<=69.9,"82",IF(J23<=74.9,"83",IF(J23<=78.9,"84",IF(J23<=78.9,"85",IF(J23>=78.9,J23," "))))))) -> 80 | M23: b. Tuntas Individu | Q23: =C23 -> Keysa Lutfi Yana Putri | R23: =IF(I23<$N$10,"84","") -> 84
A24: 17 | C24: =DATA!B26 -> Khanaya Putri Emeyliana | D24: 10 | I24: =SUM(D24:H24) -> 10 | J24: =I24 -> 10 | K24: =IF(J24<$N$10,"tdk tuntas","tuntas") -> tdk tuntas | L24: =IF(J24<=39.9,"80",IF(J24<=59.9,"81",IF(J24<=69.9,"82",IF(J24<=74.9,"83",IF(J24<=78.9,"84",IF(J24<=78.9,"85",IF(J24>=78.9,J24," "))))))) -> 80 | Q24: =C24 -> Khanaya Putri Emeyliana | R24: =IF(I24<$N$10,"82","") -> 82 | T24: Guru Mata Pelajaran
A25: 18 | C25: =DATA!B27 -> Khoirul Rodzikin | D25: 30 | I25: =SUM(D25:H25) -> 30 | J25: =I25 -> 30 | K25: =IF(J25<$N$10,"tdk tuntas","tuntas") -> tdk tuntas | L25: =IF(J25<=39.9,"80",IF(J25<=59.9,"81",IF(J25<=69.9,"82",IF(J25<=74.9,"83",IF(J25<=78.9,"84",IF(J25<=78.9,"85",IF(J25>=78.9,J25," "))))))) -> 80 | Q25: =C25 -> Khoirul Rodzikin | R25: =IF(I25<$N$10,"82","") -> 82
A26: 19 | C26: =DATA!B28 -> Livia Mozavina | D26: 50 | I26: =SUM(D26:H26) -> 50 | J26: =I26 -> 50 | K26: =IF(J26<$N$10,"tdk tuntas","tuntas") -> tdk tuntas | L26: =IF(J26<=39.9,"80",IF(J26<=59.9,"81",IF(J26<=69.9,"82",IF(J26<=74.9,"83",IF(J26<=78.9,"84",IF(J26<=78.9,"85",IF(J26>=78.9,J26," "))))))) -> 81 | Q26: =C26 -> Livia Mozavina | R26: =IF(I26<$N$10,"82","") -> 82
A27: 20 | C27: =DATA!B29 -> Milatul Ulya Azzahra | D27: 100 | I27: =SUM(D27:H27) -> 100 | J27: =I27 -> 100 | K27: =IF(J27<$N$10,"tdk tuntas","tuntas") -> tuntas | L27: =IF(J27<=39.9,"80",IF(J27<=59.9,"81",IF(J27<=69.9,"82",IF(J27<=74.9,"83",IF(J27<=78.9,"84",IF(J27<=78.9,"85",IF(J27>=78.9,J27," "))))))) -> 100 | M27: Juml nilai perolehan sw | N27: =I44 -> 1340 | Q27: =C27 -> Milatul Ulya Azzahra | R27: =IF(I27<$N$10,"82","")
A28: 21 | C28: =DATA!B30 -> Muhammad Arif Pratama | D28: 0 | I28: =SUM(D28:H28) -> 0 | J28: =I28 -> 0 | K28: =IF(J28<$N$10,"tdk tuntas","tuntas") -> tdk tuntas | L28: =IF(J28<=39.9,"80",IF(J28<=59.9,"81",IF(J28<=69.9,"82",IF(J28<=74.9,"83",IF(J28<=78.9,"84",IF(J28<=78.9,"85",IF(J28>=78.9,J28," "))))))) -> 80 | M28: Juml nili seluruhnya | N28: =I45 -> 3200 | Q28: =C28 -> Muhammad Arif Pratama | R28: =IF(I28<$N$10,"82","") -> 82 | T28: =DATA!B3 -> KASMIN, S.Pd
A29: 22 | C29: =DATA!B31 -> Muhammad Fahri Khoirudin | D29: 60 | I29: =SUM(D29:H29) -> 60 | J29: =I29 -> 60 | K29: =IF(J29<$N$10,"tdk tuntas","tuntas") -> tdk tuntas | L29: =IF(J29<=39.9,"80",IF(J29<=59.9,"81",IF(J29<=69.9,"82",IF(J29<=74.9,"83",IF(J29<=78.9,"84",IF(J29<=78.9,"85",IF(J29>=78.9,J29," "))))))) -> 82 | M29: Prosentase ketuntasan | N29: =N27/N28*100 -> 41.875 | O29: % | Q29: =C29 -> Muhammad Fahri Khoirudin | R29: =IF(I29<$N$10,"82","") -> 82 | T29: =DATA!B4 -> NIP : 196609141990031007
A30: 23 | C30: =DATA!B32 -> Muhammad Rakha Razansyah | D30: 100 | I30: =SUM(D30:H30) -> 100 | J30: =I30 -> 100 | K30: =IF(J30<$N$10,"tdk tuntas","tuntas") -> tuntas | L30: =IF(J30<=39.9,"80",IF(J30<=59.9,"81",IF(J30<=69.9,"82",IF(J30<=74.9,"83",IF(J30<=78.9,"84",IF(J30<=78.9,"85",IF(J30>=78.9,J30," "))))))) -> 100 | Q30: =C30 -> Muhammad Rakha Razansyah | R30: =IF(I30<$N$10,"82","")
A31: 24 | C31: =DATA!B33 -> Mutiara Dewi Khusna | D31: 60 | I31: =SUM(D31:H31) -> 60 | J31: =I31 -> 60 | K31: =IF(J31<$N$10,"tdk tuntas","tuntas") -> tdk tuntas | L31: =IF(J31<=39.9,"80",IF(J31<=59.9,"81",IF(J31<=69.9,"82",IF(J31<=74.9,"83",IF(J31<=78.9,"84",IF(J31<=78.9,"85",IF(J31>=78.9,J31," "))))))) -> 82 | Q31: =C31 -> Mutiara Dewi Khusna | R31: =IF(I31<$N$10,"85","") -> 85 | T31: Kepala Sekolah
A32: 25 | C32: =DATA!B34 -> Qeysya Nabila Maharani | D32: 70 | I32: =SUM(D32:H32) -> 70 | J32: =I32 -> 70 | K32: =IF(J32<$N$10,"tdk tuntas","tuntas") -> tdk tuntas | L32: =IF(J32<=39.9,"80",IF(J32<=59.9,"81",IF(J32<=69.9,"82",IF(J32<=74.9,"83",IF(J32<=78.9,"84",IF(J32<=78.9,"85",IF(J32>=78.9,J32," "))))))) -> 83 | M32: Daya serap klasikal : | Q32: =C32 -> Qeysya Nabila Maharani | R32: =IF(I32<$N$10,"81","") -> 81
A33: 26 | C33: =DATA!B35 -> Raihan Akbar Ramadhan | D33: 0 | I33: =SUM(D33:H33) -> 0 | J33: =I33 -> 0 | K33: =IF(J33<$N$10,"tdk tuntas","tuntas") -> tdk tuntas | L33: =IF(J33<=39.9,"80",IF(J33<=59.9,"81",IF(J33<=69.9,"82",IF(J33<=74.9,"83",IF(J33<=78.9,"84",IF(J33<=78.9,"85",IF(J33>=78.9,J33," "))))))) -> 80 | M33: Suatu kls dinytkn tuntas | Q33: =C33 -> Raihan Akbar Ramadhan | R33: =IF(I33<$N$10,"82","") -> 82
A34: 27 | C34: =DATA!B36 -> Ramadhani | D34: 10 | I34: =SUM(D34:H34) -> 10 | J34: =I34 -> 10 | K34: =IF(J34<$N$10,"tdk tuntas","tuntas") -> tdk tuntas | L34: =IF(J34<=39.9,"80",IF(J34<=59.9,"81",IF(J34<=69.9,"82",IF(J34<=74.9,"83",IF(J34<=78.9,"84",IF(J34<=78.9,"85",IF(J34>=78.9,J34," "))))))) -> 80 | M34: banyak siswa tts ≥ 85% | Q34: =C34 -> Ramadhani | R34: =IF(I34<$N$10,"82","") -> 82
A35: 28 | C35: =DATA!B37 -> Rangga Putra Raditya | D35: 20 | I35: =SUM(D35:H35) -> 20 | J35: =I35 -> 20 | K35: =IF(J35<$N$10,"tdk tuntas","tuntas") -> tdk tuntas | L35: =IF(J35<=39.9,"80",IF(J35<=59.9,"81",IF(J35<=69.9,"82",IF(J35<=74.9,"83",IF(J35<=78.9,"84",IF(J35<=78.9,"85",IF(J35>=78.9,J35," "))))))) -> 80 | Q35: =C35 -> Rangga Putra Raditya | R35: =IF(I35<$N$10,"81","") -> 81
A36: 29 | C36: =DATA!B38 -> Safa Nasila Anajwa | D36: 100 | I36: =SUM(D36:H36) -> 100 | J36: =I36 -> 100 | K36: =IF(J36<$N$10,"tdk tuntas","tuntas") -> tuntas | L36: =IF(J36<=39.9,"80",IF(J36<=59.9,"81",IF(J36<=69.9,"82",IF(J36<=74.9,"83",IF(J36<=78.9,"84",IF(J36<=78.9,"85",IF(J36>=78.9,J36," "))))))) -> 100 | Q36: =C36 -> Safa Nasila Anajwa | R36: =IF(I36<$N$10,"85","")
A37: 30 | C37: =DATA!B39 -> Sila Ayu Kurnia | D37: 90 | I37: =SUM(D37:H37) -> 90 | J37: =I37 -> 90 | K37: =IF(J37<$N$10,"tdk tuntas","tuntas") -> tuntas | L37: =IF(J37<=39.9,"80",IF(J37<=59.9,"81",IF(J37<=69.9,"82",IF(J37<=74.9,"83",IF(J37<=78.9,"84",IF(J37<=78.9,"85",IF(J37>=78.9,J37," "))))))) -> 90 | Q37: =C37 -> Sila Ayu Kurnia | R37: =IF(I37<$N$10,"84","") | T37: =DATA!D3 -> Dra. BAROKAH GUNIARTI
A38: 31 | C38: =DATA!B40 -> Sindhi Nandha Lusia | D38: 0 | I38: =SUM(D38:H38) -> 0 | J38: =I38 -> 0 | K38: =IF(J38<$N$10,"tdk tuntas","tuntas") -> tdk tuntas | L38: =IF(J38<=39.9,"80",IF(J38<=59.9,"81",IF(J38<=69.9,"82",IF(J38<=74.9,"83",IF(J38<=78.9,"84",IF(J38<=78.9,"85",IF(J38>=78.9,J38," "))))))) -> 80 | M38: Kesimpulan : | Q38: =C38 -> Sindhi Nandha Lusia | R38: =IF(I38<$N$10,"84","") -> 84 | T38: =DATA!D4 -> NIP : 196901081996122004
A39: 32 | C39: =DATA!B41 -> Siti Alfiani | D39: 100 | I39: =SUM(D39:H39) -> 100 | J39: =I39 -> 100 | K39: =IF(J39<$N$10,"tdk tuntas","tuntas") -> tuntas | L39: =IF(J39<=39.9,"80",IF(J39<=59.9,"81",IF(J39<=69.9,"82",IF(J39<=74.9,"83",IF(J39<=78.9,"84",IF(J39<=78.9,"85",IF(J39>=78.9,J39," "))))))) -> 100
A40: 33 | L40: =IF(J40<=39.9,"80",IF(J40<=59.9,"81",IF(J40<=69.9,"82",IF(J40<=74.9,"83",IF(J40<=78.9,"84",IF(J40<=78.9,"85",IF(J40>=78.9,J40," "))))))) -> 80 | M40: Perlu perbaikan siswa-siswa
A41: 34 | M41: yang nilainya kurang dari | N41: =N10 -> 80
...

Sheet UHB
A1: ='UH1'!A1 -> ANALISA HASIL PH MATEMATIKA KLS IX SMT GENAP | Q1: PROGRAM DAN PELAKSANAAN
A2: ='UH1'!A2 -> SMP I LIMBANGAN TH 2025/2026 | Q2: PERBAIKAN / PENGAYAAN
A4: KLS | C4: =DATA!B8 -> 9A | D4: PH ke : | F4: 2 | I4: Tanggal : | K4: 45936 | M4: SK no : | N4: 2 | Q4: Waktu pelaksanaan : | R4: =K4+7 -> 45943
C5: No Soal | D5: 1 | E5: 2 | F5: 3 | G5: 4 | H5: 5 | I5: JUM | J5: % | K5: KETUN | L5: NILAI | M5: KETERANGAN | R5: HASIL
A6: NO | B6: NIS | C6: Scor | D6: 20 | E6: 20 | F6: 30 | G6: 30 | I6: =SUM(D6:H6) -> 100 | J6: Keter | K6: TASAN | L6: SETLH | Q6: NAMA | R6: PERBK | S6: URAIAN PROGRAM
C7: NAMA | J7: capaian | L7: PERBKN | R7: PGYAAN
A8: 1 | C8: =DATA!B10 -> Affan Bagus Ramadhani | D8: 40 | I8: =SUM(D8:H8) -> 40 | J8: =I8 -> 40 | K8: =IF(J8<$N$10,"tdk tuntas","tuntas") -> tdk tuntas | L8: =IF(J8<=39.9,"80",IF(J8<=59.9,"81",IF(J8<=69.9,"82",IF(J8<=74.9,"83",IF(J8<=78.9,"84",IF(J8<=78.9,"85",IF(J8>=78.9,J8," "))))))) -> 81 | Q8: =C8 -> Affan Bagus Ramadhani | R8: =IF(I8<$N$10,"80","") -> 80
A9: 2 | C9: =DATA!B11 -> Affansa Rayya Assalafi | D9: 40 | I9: =SUM(D9:H9) -> 40 | J9: =I9 -> 40 | K9: =IF(J9<$N$10,"tdk tuntas","tuntas") -> tdk tuntas | L9: =IF(J9<=39.9,"80",IF(J9<=59.9,"81",IF(J9<=69.9,"82",IF(J9<=74.9,"83",IF(J9<=78.9,"84",IF(J9<=78.9,"85",IF(J9>=78.9,J9," "))))))) -> 81 | Q9: =C9 -> Affansa Rayya Assalafi | R9: =IF(I9<$N$10,"81","") -> 81 | S9: PERBAIKAN
A10: 3 | C10: =DATA!B12 -> Agel Fransiska | D10: 45 | I10: =SUM(D10:H10) -> 45 | J10: =I10 -> 45 | K10: =IF(J10<$N$10,"tdk tuntas","tuntas") -> tdk tuntas | L10: =IF(J10<=39.9,"80",IF(J10<=59.9,"81",IF(J10<=69.9,"82",IF(J10<=74.9,"83",IF(J10<=78.9,"84",IF(J10<=78.9,"85",IF(J10>=78.9,J10," "))))))) -> 81 | M10: KKM | N10: =DATA!F4 -> 80 | Q10: =C10 -> Agel Fransiska | R10: =IF(I10<$N$10,"81","") -> 81
A11: 4 | C11: =DATA!B13 -> Alfin Putra Firmansyah | D11: 10 | I11: =SUM(D11:H11) -> 10 | J11: =I11 -> 10 | K11: =IF(J11<$N$10,"tdk tuntas","tuntas") -> tdk tuntas | L11: =IF(J11<=39.9,"80",IF(J11<=59.9,"81",IF(J11<=69.9,"82",IF(J11<=74.9,"83",IF(J11<=78.9,"84",IF(J11<=78.9,"85",IF(J11>=78.9,J11," "))))))) -> 80 | Q11: =C11 -> Alfin Putra Firmansyah | R11: =IF(I11<$N$10,"84","") -> 84 | T11: Membuat rangkuman
A12: 5 | C12: =DATA!B14 -> Almira Sadia Qonitah | D12: 50 | I12: =SUM(D12:H12) -> 50 | J12: =I12 -> 50 | K12: =IF(J12<$N$10,"tdk tuntas","tuntas") -> tdk tuntas | L12: =IF(J12<=39.9,"80",IF(J12<=59.9,"81",IF(J12<=69.9,"82",IF(J12<=74.9,"83",IF(J12<=78.9,"84",IF(J12<=78.9,"85",IF(J12>=78.9,J12," "))))))) -> 81 | Q12: =C12 -> Almira Sadia Qonitah | R12: =IF(I12<$N$10,"87","") -> 87 | S12: v | T12: Menbuat soal
A13: 6 | C13: =DATA!B15 -> Arif Perdana Putra | D13: 25 | I13: =SUM(D13:H13) -> 25 | J13: =I13 -> 25 | K13: =IF(J13<$N$10,"tdk tuntas","tuntas") -> tdk tuntas | L13: =IF(J13<=39.9,"80",IF(J13<=59.9,"81",IF(J13<=69.9,"82",IF(J13<=74.9,"83",IF(J13<=78.9,"84",IF(J13<=78.9,"85",IF(J13>=78.9,J13," "))))))) -> 80 | M13: Hasil Analisa | Q13: =C13 -> Arif Perdana Putra | R13: =IF(I13<$N$10,"82","") -> 82 | T13: dan penyelesaiannya
A14: 7 | C14: =DATA!B16 -> Asifa Nariyati | D14: 40 | I14: =SUM(D14:H14) -> 40 | J14: =I14 -> 40 | K14: =IF(J14<$N$10,"tdk tuntas","tuntas") -> tdk tuntas | L14: =IF(J14<=39.9,"80",IF(J14<=59.9,"81",IF(J14<=69.9,"82",IF(J14<=74.9,"83",IF(J14<=78.9,"84",IF(J14<=78.9,"85",IF(J14>=78.9,J14," "))))))) -> 81 | Q14: =C14 -> Asifa Nariyati | R14: =IF(I14<$N$10,"80","") -> 80 | T14: Mengerjakan soal
A15: 8 | C15: =DATA!B17 -> Calvin Mandala Putra | D15: 35 | I15: =SUM(D15:H15) -> 35 | J15: =I15 -> 35 | K15: =IF(J15<$N$10,"tdk tuntas","tuntas") -> tdk tuntas | L15: =IF(J15<=39.9,"80",IF(J15<=59.9,"81",IF(J15<=69.9,"82",IF(J15<=74.9,"83",IF(J15<=78.9,"84",IF(J15<=78.9,"85",IF(J15>=78.9,J15," "))))))) -> 80 | M15: a. Tuntas Klasikal | Q15: =C15 -> Calvin Mandala Putra | R15: =IF(I15<$N$10,"84","") -> 84 | T15: dengan bobot sama
A16: 9 | C16: =DATA!B18 -> Decha Rifqoh Alma Dhini | D16: 25 | I16: =SUM(D16:H16) -> 25 | J16: =I16 -> 25 | K16: =IF(J16<$N$10,"tdk tuntas","tuntas") -> tdk tuntas | L16: =IF(J16<=39.9,"80",IF(J16<=59.9,"81",IF(J16<=69.9,"82",IF(J16<=74.9,"83",IF(J16<=78.9,"84",IF(J16<=78.9,"85",IF(J16>=78.9,J16," "))))))) -> 80 | Q16: =C16 -> Decha Rifqoh Alma Dhini | R16: =IF(I16<$N$10,"88","") -> 88
A17: 10 | C17: =DATA!B19 -> Fathir Hibatullah Harahap | D17: 50 | I17: =SUM(D17:H17) -> 50 | J17: =I17 -> 50 | K17: =IF(J17<$N$10,"tdk tuntas","tuntas") -> tdk tuntas | L17: =IF(J17<=39.9,"80",IF(J17<=59.9,"81",IF(J17<=69.9,"82",IF(J17<=74.9,"83",IF(J17<=78.9,"84",IF(J17<=78.9,"85",IF(J17>=78.9,J17," "))))))) -> 81 | Q17: =C17 -> Fathir Hibatullah Harahap | R17: =IF(I17<$N$10,"85","") -> 85 | S17: PENGAYAAN
A18: 11 | C18: =DATA!B20 -> Gendhis Putri Ayreanti | D18: 65 | I18: =SUM(D18:H18) -> 65 | J18: =I18 -> 65 | K18: =IF(J18<$N$10,"tdk tuntas","tuntas") -> tdk tuntas | L18: =IF(J18<=39.9,"80",IF(J18<=59.9,"81",IF(J18<=69.9,"82",IF(J18<=74.9,"83",IF(J18<=78.9,"84",IF(J18<=78.9,"85",IF(J18>=78.9,J18," "))))))) -> 82 | Q18: =C18 -> Gendhis Putri Ayreanti | R18: =IF(I18<$N$10,"85","") -> 85
A19: 12 | C19: =DATA!B21 -> Habibi Lazuardi | D19: 50 | I19: =SUM(D19:H19) -> 50 | J19: =I19 -> 50 | K19: =IF(J19<$N$10,"tdk tuntas","tuntas") -> tdk tuntas | L19: =IF(J19<=39.9,"80",IF(J19<=59.9,"81",IF(J19<=69.9,"82",IF(J19<=74.9,"83",IF(J19<=78.9,"84",IF(J19<=78.9,"85",IF(J19>=78.9,J19," "))))))) -> 81 | M19: Banyak siswa seluruhnya | N19: =K46 -> 32 | Q19: =C19 -> Habibi Lazuardi | R19: =IF(I19<$N$10,"85","") -> 85 | S19: V | T19: Menyelesaikan soal soal
A20: 13 | C20: =DATA!B22 -> Herina Sasha Rasati | D20: 45 | I20: =SUM(D20:H20) -> 45 | J20: =I20 -> 45 | K20: =IF(J20<$N$10,"tdk tuntas","tuntas") -> tdk tuntas | L20: =IF(J20<=39.9,"80",IF(J20<=59.9,"81",IF(J20<=69.9,"82",IF(J20<=74.9,"83",IF(J20<=78.9,"84",IF(J20<=78.9,"85",IF(J20>=78.9,J20," "))))))) -> 81 | M20: Banyak siswa yg tuntas | N20: =K44 -> 0 | Q20: =C20 -> Herina Sasha Rasati | R20: =IF(I20<$N$10,"85","") -> 85 | T20: pengayaan
A21: 14 | C21: =DATA!B23 -> Ivan Adi Saputra | D21: 30 | I21: =SUM(D21:H21) -> 30 | J21: =I21 -> 30 | K21: =IF(J21<$N$10,"tdk tuntas","tuntas") -> tdk tuntas | L21: =IF(J21<=39.9,"80",IF(J21<=59.9,"81",IF(J21<=69.9,"82",IF(J21<=74.9,"83",IF(J21<=78.9,"84",IF(J21<=78.9,"85",IF(J21>=78.9,J21," "))))))) -> 80 | M21: Prosentase ketuntasan | N21: =N20/N19*100 -> 0 | O21: % | Q21: =C21 -> Ivan Adi Saputra | R21: =IF(I21<$N$10,"85","") -> 85 | T21: Mempelajari materi / KD
A22: 15 | C22: =DATA!B24 -> Ivander Veda Ardyanta | D22: 65 | I22: =SUM(D22:H22) -> 65 | J22: =I22 -> 65 | K22: =IF(J22<$N$10,"tdk tuntas","tuntas") -> tdk tuntas | L22: =IF(J22<=39.9,"80",IF(J22<=59.9,"81",IF(J22<=69.9,"82",IF(J22<=74.9,"83",IF(J22<=78.9,"84",IF(J22<=78.9,"85",IF(J22>=78.9,J22," "))))))) -> 82 | Q22: =C22 -> Ivander Veda Ardyanta | R22: =IF(I22<$N$10,"85","") -> 85 | T22: berikutnya
A23: 16 | C23: =DATA!B25 -> Keysa Lutfi Yana Putri | D23: 25 | I23: =SUM(D23:H23) -> 25 | J23: =I23 -> 25 | K23: =IF(J23<$N$10,"tdk tuntas","tuntas") -> tdk tuntas | L23: =IF(J23<=39.9,"80",IF(J23<=59.9,"81",IF(J23<=69.9,"82",IF(J23<=74.9,"83",IF(J23<=78.9,"84",IF(J23<=78.9,"85",IF(J23>=78.9,J23," "))))))) -> 80 | M23: b. Tuntas Individu | Q23: =C23 -> Keysa Lutfi Yana Putri | R23: =IF(I23<$N$10,"84","") -> 84
A24: 17 | C24: =DATA!B26 -> Khanaya Putri Emeyliana | D24: 25 | I24: =SUM(D24:H24) -> 25 | J24: =I24 -> 25 | K24: =IF(J24<$N$10,"tdk tuntas","tuntas") -> tdk tuntas | L24: =IF(J24<=39.9,"80",IF(J24<=59.9,"81",IF(J24<=69.9,"82",IF(J24<=74.9,"83",IF(J24<=78.9,"84",IF(J24<=78.9,"85",IF(J24>=78.9,J24," "))))))) -> 80 | Q24: =C24 -> Khanaya Putri Emeyliana | R24: =IF(I24<$N$10,"82","") -> 82 | T24: Guru Mata Pelajaran
A25: 18 | C25: =DATA!B27 -> Khoirul Rodzikin | D25: 35 | I25: =SUM(D25:H25) -> 35 | J25: =I25 -> 35 | K25: =IF(J25<$N$10,"tdk tuntas","tuntas") -> tdk tuntas | L25: =IF(J25<=39.9,"80",IF(J25<=59.9,"81",IF(J25<=69.9,"82",IF(J25<=74.9,"83",IF(J25<=78.9,"84",IF(J25<=78.9,"85",IF(J25>=78.9,J25," "))))))) -> 80 | Q25: =C25 -> Khoirul Rodzikin | R25: =IF(I25<$N$10,"82","") -> 82
A26: 19 | C26: =DATA!B28 -> Livia Mozavina | D26: 46 | I26: =SUM(D26:H26) -> 46 | J26: =I26 -> 46 | K26: =IF(J26<$N$10,"tdk tuntas","tuntas") -> tdk tuntas | L26: =IF(J26<=39.9,"80",IF(J26<=59.9,"81",IF(J26<=69.9,"82",IF(J26<=74.9,"83",IF(J26<=78.9,"84",IF(J26<=78.9,"85",IF(J26>=78.9,J26," "))))))) -> 81 | Q26: =C26 -> Livia Mozavina | R26: =IF(I26<$N$10,"82","") -> 82
A27: 20 | C27: =DATA!B29 -> Milatul Ulya Azzahra | D27: 40 | I27: =SUM(D27:H27) -> 40 | J27: =I27 -> 40 | K27: =IF(J27<$N$10,"tdk tuntas","tuntas") -> tdk tuntas | L27: =IF(J27<=39.9,"80",IF(J27<=59.9,"81",IF(J27<=69.9,"82",IF(J27<=74.9,"83",IF(J27<=78.9,"84",IF(J27<=78.9,"85",IF(J27>=78.9,J27," "))))))) -> 81 | M27: Juml nilai perolehan sw | N27: =I44 -> 1306 | Q27: =C27 -> Milatul Ulya Azzahra | R27: =IF(I27<$N$10,"82","") -> 82
A28: 21 | C28: =DATA!B30 -> Muhammad Arif Pratama | D28: 45 | I28: =SUM(D28:H28) -> 45 | J28: =I28 -> 45 | K28: =IF(J28<$N$10,"tdk tuntas","tuntas") -> tdk tuntas | L28: =IF(J28<=39.9,"80",IF(J28<=59.9,"81",IF(J28<=69.9,"82",IF(J28<=74.9,"83",IF(J28<=78.9,"84",IF(J28<=78.9,"85",IF(J28>=78.9,J28," "))))))) -> 81 | M28: Juml nili seluruhnya | N28: =I45 -> 3200 | Q28: =C28 -> Muhammad Arif Pratama | R28: =IF(I28<$N$10,"82","") -> 82 | T28: =DATA!B3 -> KASMIN, S.Pd
A29: 22 | C29: =DATA!B31 -> Muhammad Fahri Khoirudin | D29: 45 | I29: =SUM(D29:H29) -> 45 | J29: =I29 -> 45 | K29: =IF(J29<$N$10,"tdk tuntas","tuntas") -> tdk tuntas | L29: =IF(J29<=39.9,"80",IF(J29<=59.9,"81",IF(J29<=69.9,"82",IF(J29<=74.9,"83",IF(J29<=78.9,"84",IF(J29<=78.9,"85",IF(J29>=78.9,J29," "))))))) -> 81 | M29: Prosentase ketuntasan | N29: =N27/N28*100 -> 40.8125 | O29: % | Q29: =C29 -> Muhammad Fahri Khoirudin | R29: =IF(I29<$N$10,"82","") -> 82 | T29: =DATA!B4 -> NIP : 196609141990031007
A30: 23 | C30: =DATA!B32 -> Muhammad Rakha Razansyah | D30: 60 | I30: =SUM(D30:H30) -> 60 | J30: =I30 -> 60 | K30: =IF(J30<$N$10,"tdk tuntas","tuntas") -> tdk tuntas | L30: =IF(J30<=39.9,"80",IF(J30<=59.9,"81",IF(J30<=69.9,"82",IF(J30<=74.9,"83",IF(J30<=78.9,"84",IF(J30<=78.9,"85",IF(J30>=78.9,J30," "))))))) -> 82 | Q30: =C30 -> Muhammad Rakha Razansyah | R30: =IF(I30<$N$10,"82","") -> 82
A31: 24 | C31: =DATA!B33 -> Mutiara Dewi Khusna | D31: 25 | I31: =SUM(D31:H31) -> 25 | J31: =I31 -> 25 | K31: =IF(J31<$N$10,"tdk tuntas","tuntas") -> tdk tuntas | L31: =IF(J31<=39.9,"80",IF(J31<=59.9,"81",IF(J31<=69.9,"82",IF(J31<=74.9,"83",IF(J31<=78.9,"84",IF(J31<=78.9,"85",IF(J31>=78.9,J31," "))))))) -> 80 | Q31: =C31 -> Mutiara Dewi Khusna | R31: =IF(I31<$N$10,"85","") -> 85 | T31: Kepala Sekolah
A32: 25 | C32: =DATA!B34 -> Qeysya Nabila Maharani | D32: 40 | I32: =SUM(D32:H32) -> 40 | J32: =I32 -> 40 | K32: =IF(J32<$N$10,"tdk tuntas","tuntas") -> tdk tuntas | L32: =IF(J32<=39.9,"80",IF(J32<=59.9,"81",IF(J32<=69.9,"82",IF(J32<=74.9,"83",IF(J32<=78.9,"84",IF(J32<=78.9,"85",IF(J32>=78.9,J32," "))))))) -> 81 | M32: Daya serap klasikal : | Q32: =C32 -> Qeysya Nabila Maharani | R32: =IF(I32<$N$10,"81","") -> 81
A33: 26 | C33: =DATA!B35 -> Raihan Akbar Ramadhan | D33: 60 | I33: =SUM(D33:H33) -> 60 | J33: =I33 -> 60 | K33: =IF(J33<$N$10,"tdk tuntas","tuntas") -> tdk tuntas | L33: =IF(J33<=39.9,"80",IF(J33<=59.9,"81",IF(J33<=69.9,"82",IF(J33<=74.9,"83",IF(J33<=78.9,"84",IF(J33<=78.9,"85",IF(J33>=78.9,J33," "))))))) -> 82 | M33: Suatu kls dinytkn tuntas | Q33: =C33 -> Raihan Akbar Ramadhan | R33: =IF(I33<$N$10,"82","") -> 82
A34: 27 | C34: =DATA!B36 -> Ramadhani | D34: 40 | I34: =SUM(D34:H34) -> 40 | J34: =I34 -> 40 | K34: =IF(J34<$N$10,"tdk tuntas","tuntas") -> tdk tuntas | L34: =IF(J34<=39.9,"80",IF(J34<=59.9,"81",IF(J34<=69.9,"82",IF(J34<=74.9,"83",IF(J34<=78.9,"84",IF(J34<=78.9,"85",IF(J34>=78.9,J34," "))))))) -> 81 | M34: banyak siswa tts ≥ 85% | Q34: =C34 -> Ramadhani | R34: =IF(I34<$N$10,"82","") -> 82
A35: 28 | C35: =DATA!B37 -> Rangga Putra Raditya | D35: 20 | I35: =SUM(D35:H35) -> 20 | J35: =I35 -> 20 | K35: =IF(J35<$N$10,"tdk tuntas","tuntas") -> tdk tuntas | L35: =IF(J35<=39.9,"80",IF(J35<=59.9,"81",IF(J35<=69.9,"82",IF(J35<=74.9,"83",IF(J35<=78.9,"84",IF(J35<=78.9,"85",IF(J35>=78.9,J35," "))))))) -> 80 | Q35: =C35 -> Rangga Putra Raditya | R35: =IF(I35<$N$10,"81","") -> 81
A36: 29 | C36: =DATA!B38 -> Safa Nasila Anajwa | D36: 45 | I36: =SUM(D36:H36) -> 45 | J36: =I36 -> 45 | K36: =IF(J36<$N$10,"tdk tuntas","tuntas") -> tdk tuntas | L36: =IF(J36<=39.9,"80",IF(J36<=59.9,"81",IF(J36<=69.9,"82",IF(J36<=74.9,"83",IF(J36<=78.9,"84",IF(J36<=78.9,"85",IF(J36>=78.9,J36," "))))))) -> 81 | Q36: =C36 -> Safa Nasila Anajwa | R36: =IF(I36<$N$10,"85","") -> 85
A37: 30 | C37: =DATA!B39 -> Sila Ayu Kurnia | D37: 50 | I37: =SUM(D37:H37) -> 50 | J37: =I37 -> 50 | K37: =IF(J37<$N$10,"tdk tuntas","tuntas") -> tdk tuntas | L37: =IF(J37<=39.9,"80",IF(J37<=59.9,"81",IF(J37<=69.9,"82",IF(J37<=74.9,"83",IF(J37<=78.9,"84",IF(J37<=78.9,"85",IF(J37>=78.9,J37," "))))))) -> 81 | Q37: =C37 -> Sila Ayu Kurnia | R37: =IF(I37<$N$10,"84","") -> 84 | T37: =DATA!D3 -> Dra. BAROKAH GUNIARTI
A38: 31 | C38: =DATA!B40 -> Sindhi Nandha Lusia | D38: 40 | I38: =SUM(D38:H38) -> 40 | J38: =I38 -> 40 | K38: =IF(J38<$N$10,"tdk tuntas","tuntas") -> tdk tuntas | L38: =IF(J38<=39.9,"80",IF(J38<=59.9,"81",IF(J38<=69.9,"82",IF(J38<=74.9,"83",IF(J38<=78.9,"84",IF(J38<=78.9,"85",IF(J38>=78.9,J38," "))))))) -> 81 | M38: Kesimpulan : | Q38: =C38 -> Sindhi Nandha Lusia | R38: =IF(I38<$N$10,"84","") -> 84 | T38: =DATA!D4 -> NIP : 196901081996122004
A39: 32 | C39: =DATA!B41 -> Siti Alfiani | D39: 50 | I39: =SUM(D39:H39) -> 50 | J39: =I39 -> 50 | K39: =IF(J39<$N$10,"tdk tuntas","tuntas") -> tdk tuntas | L39: =IF(J39<=39.9,"80",IF(J39<=59.9,"81",IF(J39<=69.9,"82",IF(J39<=74.9,"83",IF(J39<=78.9,"84",IF(J39<=78.9,"85",IF(J39>=78.9,J39," "))))))) -> 81
A40: 33 | M40: Perlu perbaikan siswa-siswa
A41: 34 | M41: yang nilainya < KKM.
...

Sheet UH3
A1: ='UH1'!A1 -> ANALISA HASIL PH MATEMATIKA KLS IX SMT GENAP | Q1: PROGRAM DAN PELAKSANAAN
A2: ='UH1'!A2 -> SMP I LIMBANGAN TH 2025/2026 | Q2: PERBAIKAN / PENGAYAAN
A4: KLS | C4: =DATA!B8 -> 9A | D4: UH ke : | F4: 3 | I4: Tanggal : | K4: 45971 | M4: SK no : | N4: 3 | Q4: Waktu pelaksanaan : | R4: =K4+7 -> 45978
C5: No Soal | D5: 1 | E5: 2 | F5: 3 | G5: 4 | H5: 5 | I5: JUM | J5: % | K5: KETUN | L5: NILAI | M5: KETERANGAN | R5: HASIL
A6: NO | B6: NIS | C6: Scor | D6: 20 | E6: 20 | F6: 20 | G6: 20 | H6: 20 | I6: =SUM(D6:H6) -> 100 | J6: Keter | K6: TASAN | L6: SETLH | Q6: NAMA | R6: PERBK | S6: URAIAN PROGRAM
C7: NAMA | J7: capaian | L7: PERBKN | R7: PGYAAN
A8: 1 | C8: =DATA!B10 -> Affan Bagus Ramadhani | I8: =SUM(D8:H8) -> 0 | J8: =I8 -> 0 | K8: =IF(J8<$N$10,"tdk tuntas","tuntas") -> tdk tuntas | L8: =IF(J8<=39.9,"80",IF(J8<=59.9,"81",IF(J8<=69.9,"82",IF(J8<=74.9,"83",IF(J8<=78.9,"84",IF(J8<=78.9,"85",IF(J8>=78.9,J8," "))))))) -> 80 | Q8: =C8 -> Affan Bagus Ramadhani | R8: =IF(I8<$N$10,"80","") -> 80
A9: 2 | C9: =DATA!B11 -> Affansa Rayya Assalafi | I9: =SUM(D9:H9) -> 0 | J9: =I9 -> 0 | K9: =IF(J9<$N$10,"tdk tuntas","tuntas") -> tdk tuntas | L9: =IF(J9<=39.9,"80",IF(J9<=59.9,"81",IF(J9<=69.9,"82",IF(J9<=74.9,"83",IF(J9<=78.9,"84",IF(J9<=78.9,"85",IF(J9>=78.9,J9," "))))))) -> 80 | Q9: =C9 -> Affansa Rayya Assalafi | R9: =IF(I9<$N$10,"81","") -> 81 | S9: PERBAIKAN
A10: 3 | C10: =DATA!B12 -> Agel Fransiska | I10: =SUM(D10:H10) -> 0 | J10: =I10 -> 0 | K10: =IF(J10<$N$10,"tdk tuntas","tuntas") -> tdk tuntas | L10: =IF(J10<=39.9,"80",IF(J10<=59.9,"81",IF(J10<=69.9,"82",IF(J10<=74.9,"83",IF(J10<=78.9,"84",IF(J10<=78.9,"85",IF(J10>=78.9,J10," "))))))) -> 80 | M10: KKM | N10: =DATA!F4 -> 80 | Q10: =C10 -> Agel Fransiska | R10: =IF(I10<$N$10,"81","") -> 81
A11: 4 | C11: =DATA!B13 -> Alfin Putra Firmansyah | I11: =SUM(D11:H11) -> 0 | J11: =I11 -> 0 | K11: =IF(J11<$N$10,"tdk tuntas","tuntas") -> tdk tuntas | L11: =IF(J11<=39.9,"80",IF(J11<=59.9,"81",IF(J11<=69.9,"82",IF(J11<=74.9,"83",IF(J11<=78.9,"84",IF(J11<=78.9,"85",IF(J11>=78.9,J11," "))))))) -> 80 | Q11: =C11 -> Alfin Putra Firmansyah | R11: =IF(I11<$N$10,"84","") -> 84 | T11: Membuat rangkuman
A12: 5 | C12: =DATA!B14 -> Almira Sadia Qonitah | I12: =SUM(D12:H12) -> 0 | J12: =I12 -> 0 | K12: =IF(J12<$N$10,"tdk tuntas","tuntas") -> tdk tuntas | L12: =IF(J12<=39.9,"80",IF(J12<=59.9,"81",IF(J12<=69.9,"82",IF(J12<=74.9,"83",IF(J12<=78.9,"84",IF(J12<=78.9,"85",IF(J12>=78.9,J12," "))))))) -> 80 | Q12: =C12 -> Almira Sadia Qonitah | R12: =IF(I12<$N$10,"87","") -> 87 | T12: Menbuat soal
A13: 6 | C13: =DATA!B15 -> Arif Perdana Putra | I13: =SUM(D13:H13) -> 0 | J13: =I13 -> 0 | K13: =IF(J13<$N$10,"tdk tuntas","tuntas") -> tdk tuntas | L13: =IF(J13<=39.9,"80",IF(J13<=59.9,"81",IF(J13<=69.9,"82",IF(J13<=74.9,"83",IF(J13<=78.9,"84",IF(J13<=78.9,"85",IF(J13>=78.9,J13," "))))))) -> 80 | M13: Hasil Analisa | Q13: =C13 -> Arif Perdana Putra | R13: =IF(I13<$N$10,"82","") -> 82 | T13: dan penyelesaiannya
A14: 7 | C14: =DATA!B16 -> Asifa Nariyati | I14: =SUM(D14:H14) -> 0 | J14: =I14 -> 0 | K14: =IF(J14<$N$10,"tdk tuntas","tuntas") -> tdk tuntas | L14: =IF(J14<=39.9,"80",IF(J14<=59.9,"81",IF(J14<=69.9,"82",IF(J14<=74.9,"83",IF(J14<=78.9,"84",IF(J14<=78.9,"85",IF(J14>=78.9,J14," "))))))) -> 80 | Q14: =C14 -> Asifa Nariyati | R14: =IF(I14<$N$10,"80","") -> 80 | S14: v | T14: Mengerjakan soal
A15: 8 | C15: =DATA!B17 -> Calvin Mandala Putra | I15: =SUM(D15:H15) -> 0 | J15: =I15 -> 0 | K15: =IF(J15<$N$10,"tdk tuntas","tuntas") -> tdk tuntas | L15: =IF(J15<=39.9,"80",IF(J15<=59.9,"81",IF(J15<=69.9,"82",IF(J15<=74.9,"83",IF(J15<=78.9,"84",IF(J15<=78.9,"85",IF(J15>=78.9,J15," "))))))) -> 80 | M15: a. Tuntas Klasikal | Q15: =C15 -> Calvin Mandala Putra | R15: =IF(I15<$N$10,"84","") -> 84 | T15: dengan bobot sama
A16: 9 | C16: =DATA!B18 -> Decha Rifqoh Alma Dhini | I16: =SUM(D16:H16) -> 0 | J16: =I16 -> 0 | K16: =IF(J16<$N$10,"tdk tuntas","tuntas") -> tdk tuntas | L16: =IF(J16<=39.9,"80",IF(J16<=59.9,"81",IF(J16<=69.9,"82",IF(J16<=74.9,"83",IF(J16<=78.9,"84",IF(J16<=78.9,"85",IF(J16>=78.9,J16," "))))))) -> 80 | Q16: =C16 -> Decha Rifqoh Alma Dhini | R16: =IF(I16<$N$10,"88","") -> 88
A17: 10 | C17: =DATA!B19 -> Fathir Hibatullah Harahap | I17: =SUM(D17:H17) -> 0 | J17: =I17 -> 0 | K17: =IF(J17<$N$10,"tdk tuntas","tuntas") -> tdk tuntas | L17: =IF(J17<=39.9,"80",IF(J17<=59.9,"81",IF(J17<=69.9,"82",IF(J17<=74.9,"83",IF(J17<=78.9,"84",IF(J17<=78.9,"85",IF(J17>=78.9,J17," "))))))) -> 80 | Q17: =C17 -> Fathir Hibatullah Harahap | R17: =IF(I17<$N$10,"85","") -> 85 | S17: PENGAYAAN
A18: 11 | C18: =DATA!B20 -> Gendhis Putri Ayreanti | I18: =SUM(D18:H18) -> 0 | J18: =I18 -> 0 | K18: =IF(J18<$N$10,"tdk tuntas","tuntas") -> tdk tuntas | L18: =IF(J18<=39.9,"80",IF(J18<=59.9,"81",IF(J18<=69.9,"82",IF(J18<=74.9,"83",IF(J18<=78.9,"84",IF(J18<=78.9,"85",IF(J18>=78.9,J18," "))))))) -> 80 | Q18: =C18 -> Gendhis Putri Ayreanti | R18: =IF(I18<$N$10,"85","") -> 85
A19: 12 | C19: =DATA!B21 -> Habibi Lazuardi | I19: =SUM(D19:H19) -> 0 | J19: =I19 -> 0 | K19: =IF(J19<$N$10,"tdk tuntas","tuntas") -> tdk tuntas | L19: =IF(J19<=39.9,"80",IF(J19<=59.9,"81",IF(J19<=69.9,"82",IF(J19<=74.9,"83",IF(J19<=78.9,"84",IF(J19<=78.9,"85",IF(J19>=78.9,J19," "))))))) -> 80 | M19: Banyak siswa seluruhnya | N19: =K46 -> 32 | Q19: =C19 -> Habibi Lazuardi | R19: =IF(I19<$N$10,"85","") -> 85 | S19: V | T19: Menyelesaikan soal soal
A20: 13 | C20: =DATA!B22 -> Herina Sasha Rasati | I20: =SUM(D20:H20) -> 0 | J20: =I20 -> 0 | K20: =IF(J20<$N$10,"tdk tuntas","tuntas") -> tdk tuntas | L20: =IF(J20<=39.9,"80",IF(J20<=59.9,"81",IF(J20<=69.9,"82",IF(J20<=74.9,"83",IF(J20<=78.9,"84",IF(J20<=78.9,"85",IF(J20>=78.9,J20," "))))))) -> 80 | M20: Banyak siswa yg tuntas | N20: =K44 -> 0 | Q20: =C20 -> Herina Sasha Rasati | R20: =IF(I20<$N$10,"85","") -> 85 | T20: pengayaan
A21: 14 | C21: =DATA!B23 -> Ivan Adi Saputra | I21: =SUM(D21:H21) -> 0 | J21: =I21 -> 0 | K21: =IF(J21<$N$10,"tdk tuntas","tuntas") -> tdk tuntas | L21: =IF(J21<=39.9,"80",IF(J21<=59.9,"81",IF(J21<=69.9,"82",IF(J21<=74.9,"83",IF(J21<=78.9,"84",IF(J21<=78.9,"85",IF(J21>=78.9,J21," "))))))) -> 80 | M21: Prosentase ketuntasan | N21: =N20/N19*100 -> 0 | O21: % | Q21: =C21 -> Ivan Adi Saputra | R21: =IF(I21<$N$10,"85","") -> 85 | T21: Mempelajari materi / KD
A22: 15 | C22: =DATA!B24 -> Ivander Veda Ardyanta | I22: =SUM(D22:H22) -> 0 | J22: =I22 -> 0 | K22: =IF(J22<$N$10,"tdk tuntas","tuntas") -> tdk tuntas | L22: =IF(J22<=39.9,"80",IF(J22<=59.9,"81",IF(J22<=69.9,"82",IF(J22<=74.9,"83",IF(J22<=78.9,"84",IF(J22<=78.9,"85",IF(J22>=78.9,J22," "))))))) -> 80 | Q22: =C22 -> Ivander Veda Ardyanta | R22: =IF(I22<$N$10,"85","") -> 85 | T22: berikutnya
A23: 16 | C23: =DATA!B25 -> Keysa Lutfi Yana Putri | I23: =SUM(D23:H23) -> 0 | J23: =I23 -> 0 | K23: =IF(J23<$N$10,"tdk tuntas","tuntas") -> tdk tuntas | L23: =IF(J23<=39.9,"80",IF(J23<=59.9,"81",IF(J23<=69.9,"82",IF(J23<=74.9,"83",IF(J23<=78.9,"84",IF(J23<=78.9,"85",IF(J23>=78.9,J23," "))))))) -> 80 | M23: b. Tuntas Individu | Q23: =C23 -> Keysa Lutfi Yana Putri | R23: =IF(I23<$N$10,"84","") -> 84
A24: 17 | C24: =DATA!B26 -> Khanaya Putri Emeyliana | I24: =SUM(D24:H24) -> 0 | J24: =I24 -> 0 | K24: =IF(J24<$N$10,"tdk tuntas","tuntas") -> tdk tuntas | L24: =IF(J24<=39.9,"80",IF(J24<=59.9,"81",IF(J24<=69.9,"82",IF(J24<=74.9,"83",IF(J24<=78.9,"84",IF(J24<=78.9,"85",IF(J24>=78.9,J24," "))))))) -> 80 | Q24: =C24 -> Khanaya Putri Emeyliana | R24: =IF(I24<$N$10,"82","") -> 82 | T24: Guru Mata Pelajaran
A25: 18 | C25: =DATA!B27 -> Khoirul Rodzikin | I25: =SUM(D25:H25) -> 0 | J25: =I25 -> 0 | K25: =IF(J25<$N$10,"tdk tuntas","tuntas") -> tdk tuntas | L25: =IF(J25<=39.9,"80",IF(J25<=59.9,"81",IF(J25<=69.9,"82",IF(J25<=74.9,"83",IF(J25<=78.9,"84",IF(J25<=78.9,"85",IF(J25>=78.9,J25," "))))))) -> 80 | Q25: =C25 -> Khoirul Rodzikin | R25: =IF(I25<$N$10,"82","") -> 82
A26: 19 | C26: =DATA!B28 -> Livia Mozavina | I26: =SUM(D26:H26) -> 0 | J26: =I26 -> 0 | K26: =IF(J26<$N$10,"tdk tuntas","tuntas") -> tdk tuntas | L26: =IF(J26<=39.9,"80",IF(J26<=59.9,"81",IF(J26<=69.9,"82",IF(J26<=74.9,"83",IF(J26<=78.9,"84",IF(J26<=78.9,"85",IF(J26>=78.9,J26," "))))))) -> 80 | Q26: =C26 -> Livia Mozavina | R26: =IF(I26<$N$10,"82","") -> 82
A27: 20 | C27: =DATA!B29 -> Milatul Ulya Azzahra | I27: =SUM(D27:H27) -> 0 | J27: =I27 -> 0 | K27: =IF(J27<$N$10,"tdk tuntas","tuntas") -> tdk tuntas | L27: =IF(J27<=39.9,"80",IF(J27<=59.9,"81",IF(J27<=69.9,"82",IF(J27<=74.9,"83",IF(J27<=78.9,"84",IF(J27<=78.9,"85",IF(J27>=78.9,J27," "))))))) -> 80 | M27: Juml nilai perolehan sw | N27: =I44 -> 0 | Q27: =C27 -> Milatul Ulya Azzahra | R27: =IF(I27<$N$10,"82","") -> 82
A28: 21 | C28: =DATA!B30 -> Muhammad Arif Pratama | I28: =SUM(D28:H28) -> 0 | J28: =I28 -> 0 | K28: =IF(J28<$N$10,"tdk tuntas","tuntas") -> tdk tuntas | L28: =IF(J28<=39.9,"80",IF(J28<=59.9,"81",IF(J28<=69.9,"82",IF(J28<=74.9,"83",IF(J28<=78.9,"84",IF(J28<=78.9,"85",IF(J28>=78.9,J28," "))))))) -> 80 | M28: Juml nili seluruhnya | N28: =I45 -> 3200 | Q28: =C28 -> Muhammad Arif Pratama | R28: =IF(I28<$N$10,"82","") -> 82 | T28: =DATA!B3 -> KASMIN, S.Pd
A29: 22 | C29: =DATA!B31 -> Muhammad Fahri Khoirudin | I29: =SUM(D29:H29) -> 0 | J29: =I29 -> 0 | K29: =IF(J29<$N$10,"tdk tuntas","tuntas") -> tdk tuntas | L29: =IF(J29<=39.9,"80",IF(J29<=59.9,"81",IF(J29<=69.9,"82",IF(J29<=74.9,"83",IF(J29<=78.9,"84",IF(J29<=78.9,"85",IF(J29>=78.9,J29," "))))))) -> 80 | M29: Prosentase ketuntasan | N29: =N27/N28*100 -> 0 | O29: % | Q29: =C29 -> Muhammad Fahri Khoirudin | R29: =IF(I29<$N$10,"82","") -> 82 | T29: =DATA!B4 -> NIP : 196609141990031007
A30: 23 | C30: =DATA!B32 -> Muhammad Rakha Razansyah | I30: =SUM(D30:H30) -> 0 | J30: =I30 -> 0 | K30: =IF(J30<$N$10,"tdk tuntas","tuntas") -> tdk tuntas | L30: =IF(J30<=39.9,"80",IF(J30<=59.9,"81",IF(J30<=69.9,"82",IF(J30<=74.9,"83",IF(J30<=78.9,"84",IF(J30<=78.9,"85",IF(J30>=78.9,J30," "))))))) -> 80 | Q30: =C30 -> Muhammad Rakha Razansyah | R30: =IF(I30<$N$10,"82","") -> 82
A31: 24 | C31: =DATA!B33 -> Mutiara Dewi Khusna | I31: =SUM(D31:H31) -> 0 | J31: =I31 -> 0 | K31: =IF(J31<$N$10,"tdk tuntas","tuntas") -> tdk tuntas | L31: =IF(J31<=39.9,"80",IF(J31<=59.9,"81",IF(J31<=69.9,"82",IF(J31<=74.9,"83",IF(J31<=78.9,"84",IF(J31<=78.9,"85",IF(J31>=78.9,J31," "))))))) -> 80 | Q31: =C31 -> Mutiara Dewi Khusna | R31: =IF(I31<$N$10,"85","") -> 85
A32: 25 | C32: =DATA!B34 -> Qeysya Nabila Maharani | I32: =SUM(D32:H32) -> 0 | J32: =I32 -> 0 | K32: =IF(J32<$N$10,"tdk tuntas","tuntas") -> tdk tuntas | L32: =IF(J32<=39.9,"80",IF(J32<=59.9,"81",IF(J32<=69.9,"82",IF(J32<=74.9,"83",IF(J32<=78.9,"84",IF(J32<=78.9,"85",IF(J32>=78.9,J32," "))))))) -> 80 | M32: Daya serap klasikal : | Q32: =C32 -> Qeysya Nabila Maharani | R32: =IF(I32<$N$10,"81","") -> 81 | T32: Kepala Sekolah
A33: 26 | C33: =DATA!B35 -> Raihan Akbar Ramadhan | I33: =SUM(D33:H33) -> 0 | J33: =I33 -> 0 | K33: =IF(J33<$N$10,"tdk tuntas","tuntas") -> tdk tuntas | L33: =IF(J33<=39.9,"80",IF(J33<=59.9,"81",IF(J33<=69.9,"82",IF(J33<=74.9,"83",IF(J33<=78.9,"84",IF(J33<=78.9,"85",IF(J33>=78.9,J33," "))))))) -> 80 | M33: Suatu kls dinytkn tuntas | Q33: =C33 -> Raihan Akbar Ramadhan | R33: =IF(I33<$N$10,"82","") -> 82
A34: 27 | C34: =DATA!B36 -> Ramadhani | I34: =SUM(D34:H34) -> 0 | J34: =I34 -> 0 | K34: =IF(J34<$N$10,"tdk tuntas","tuntas") -> tdk tuntas | L34: =IF(J34<=39.9,"80",IF(J34<=59.9,"81",IF(J34<=69.9,"82",IF(J34<=74.9,"83",IF(J34<=78.9,"84",IF(J34<=78.9,"85",IF(J34>=78.9,J34," "))))))) -> 80 | M34: banyak siswa tts ≥ 85% | Q34: =C34 -> Ramadhani | R34: =IF(I34<$N$10,"82","") -> 82
A35: 28 | C35: =DATA!B37 -> Rangga Putra Raditya | I35: =SUM(D35:H35) -> 0 | J35: =I35 -> 0 | K35: =IF(J35<$N$10,"tdk tuntas","tuntas") -> tdk tuntas | L35: =IF(J35<=39.9,"80",IF(J35<=59.9,"81",IF(J35<=69.9,"82",IF(J35<=74.9,"83",IF(J35<=78.9,"84",IF(J35<=78.9,"85",IF(J35>=78.9,J35," "))))))) -> 80 | Q35: =C35 -> Rangga Putra Raditya | R35: =IF(I35<$N$10,"81","") -> 81
A36: 29 | C36: =DATA!B38 -> Safa Nasila Anajwa | I36: =SUM(D36:H36) -> 0 | J36: =I36 -> 0 | K36: =IF(J36<$N$10,"tdk tuntas","tuntas") -> tdk tuntas | L36: =IF(J36<=39.9,"80",IF(J36<=59.9,"81",IF(J36<=69.9,"82",IF(J36<=74.9,"83",IF(J36<=78.9,"84",IF(J36<=78.9,"85",IF(J36>=78.9,J36," "))))))) -> 80 | Q36: =C36 -> Safa Nasila Anajwa | R36: =IF(I36<$N$10,"85","") -> 85
A37: 30 | C37: =DATA!B39 -> Sila Ayu Kurnia | I37: =SUM(D37:H37) -> 0 | J37: =I37 -> 0 | K37: =IF(J37<$N$10,"tdk tuntas","tuntas") -> tdk tuntas | L37: =IF(J37<=39.9,"80",IF(J37<=59.9,"81",IF(J37<=69.9,"82",IF(J37<=74.9,"83",IF(J37<=78.9,"84",IF(J37<=78.9,"85",IF(J37>=78.9,J37," "))))))) -> 80 | Q37: =C37 -> Sila Ayu Kurnia | R37: =IF(I37<$N$10,"84","") -> 84 | T37: =DATA!D3 -> Dra. BAROKAH GUNIARTI
A38: 31 | C38: =DATA!B40 -> Sindhi Nandha Lusia | I38: =SUM(D38:H38) -> 0 | J38: =I38 -> 0 | K38: =IF(J38<$N$10,"tdk tuntas","tuntas") -> tdk tuntas | L38: =IF(J38<=39.9,"80",IF(J38<=59.9,"81",IF(J38<=69.9,"82",IF(J38<=74.9,"83",IF(J38<=78.9,"84",IF(J38<=78.9,"85",IF(J38>=78.9,J38," "))))))) -> 80 | M38: Kesimpulan : | Q38: =C38 -> Sindhi Nandha Lusia | R38: =IF(I38<$N$10,"84","") -> 84 | T38: =DATA!D4 -> NIP : 196901081996122004
A39: 32 | C39: =DATA!B41 -> Siti Alfiani | I39: =SUM(D39:H39) -> 0 | J39: =I39 -> 0 | K39: =IF(J39<$N$10,"tdk tuntas","tuntas") -> tdk tuntas | L39: =IF(J39<=39.9,"80",IF(J39<=59.9,"81",IF(J39<=69.9,"82",IF(J39<=74.9,"83",IF(J39<=78.9,"84",IF(J39<=78.9,"85",IF(J39>=78.9,J39," "))))))) -> 80
A40: 33 | M40: Perlu perbaikan siswa-siswa
A41: 34 | M41: yang nilainya < KKM.
...

Sheet UH4
A1: ='UH1'!A1 -> ANALISA HASIL PH MATEMATIKA KLS IX SMT GENAP | Q1: PROGRAM DAN PELAKSANAAN
A2: ='UH1'!A2 -> SMP I LIMBANGAN TH 2025/2026 | Q2: PERBAIKAN / PENGAYAAN
A4: KLS | C4: =DATA!B8 -> 9A | D4: UH ke : | F4: 4 | I4: Tanggal : | M4: SK no : | N4: 1 | Q4: Waktu pelaksanaan :
C5: No Soal | D5: 1 | E5: 2 | F5: 3 | G5: 4 | H5: 5 | I5: JUM | J5: % | K5: KETUN | L5: NILAI | M5: KETERANGAN | R5: HASIL
A6: NO | B6: NIS | C6: Scor | D6: 20 | E6: 20 | F6: 20 | G6: 20 | H6: 20 | I6: =SUM(D6:H6) -> 100 | J6: Keter | K6: TASAN | L6: SETLH | Q6: NAMA | R6: PERBK | S6: URAIAN PROGRAM
C7: NAMA | J7: capaian | L7: PERBKN | R7: PGYAAN
A8: 1 | C8: =DATA!B10 -> Affan Bagus Ramadhani | I8: =SUM(D8:H8) -> 0 | J8: =I8 -> 0 | K8: =IF(J8<$N$10,"tdk tuntas","tuntas") -> tdk tuntas | L8: =IF(J8<=39.9,"77",IF(J8<=59.9,"78",IF(J8<=69.9,"79",IF(J8<=74.9,"79",IF(J8<=78.9,"79",IF(J8<=78.9,"79",IF(J8>=78.9,J8," "))))))) -> 77 | Q8: =C8 -> Affan Bagus Ramadhani | R8: =IF(I8<$N$10,"80","") -> 80
A9: 2 | C9: =DATA!B11 -> Affansa Rayya Assalafi | I9: =SUM(D9:H9) -> 0 | J9: =I9 -> 0 | K9: =IF(J9<$N$10,"tdk tuntas","tuntas") -> tdk tuntas | L9: =IF(J9<=39.9,"77",IF(J9<=59.9,"78",IF(J9<=69.9,"79",IF(J9<=74.9,"79",IF(J9<=78.9,"79",IF(J9<=78.9,"79",IF(J9>=78.9,J9," "))))))) -> 77 | Q9: =C9 -> Affansa Rayya Assalafi | R9: =IF(I9<$N$10,"79","") -> 79 | S9: PERBAIKAN
A10: 3 | C10: =DATA!B12 -> Agel Fransiska | I10: =SUM(D10:H10) -> 0 | J10: =I10 -> 0 | K10: =IF(J10<$N$10,"tdk tuntas","tuntas") -> tdk tuntas | L10: =IF(J10<=39.9,"77",IF(J10<=59.9,"78",IF(J10<=69.9,"79",IF(J10<=74.9,"79",IF(J10<=78.9,"79",IF(J10<=78.9,"79",IF(J10>=78.9,J10," "))))))) -> 77 | M10: KKM | N10: =DATA!F4 -> 80 | Q10: =C10 -> Agel Fransiska | R10: =IF(I10<$N$10,"81","") -> 81
A11: 4 | C11: =DATA!B13 -> Alfin Putra Firmansyah | I11: =SUM(D11:H11) -> 0 | J11: =I11 -> 0 | K11: =IF(J11<$N$10,"tdk tuntas","tuntas") -> tdk tuntas | L11: =IF(J11<=39.9,"77",IF(J11<=59.9,"78",IF(J11<=69.9,"79",IF(J11<=74.9,"79",IF(J11<=78.9,"79",IF(J11<=78.9,"79",IF(J11>=78.9,J11," "))))))) -> 77 | Q11: =C11 -> Alfin Putra Firmansyah | R11: =IF(I11<$N$10,"79","") -> 79 | T11: Membuat rangkuman
A12: 5 | C12: =DATA!B14 -> Almira Sadia Qonitah | I12: =SUM(D12:H12) -> 0 | J12: =I12 -> 0 | K12: =IF(J12<$N$10,"tdk tuntas","tuntas") -> tdk tuntas | L12: =IF(J12<=39.9,"77",IF(J12<=59.9,"78",IF(J12<=69.9,"79",IF(J12<=74.9,"79",IF(J12<=78.9,"79",IF(J12<=78.9,"79",IF(J12>=78.9,J12," "))))))) -> 77 | Q12: =C12 -> Almira Sadia Qonitah | R12: =IF(I12<$N$10,"79","") -> 79 | T12: Menbuat soal
A13: 6 | C13: =DATA!B15 -> Arif Perdana Putra | I13: =SUM(D13:H13) -> 0 | J13: =I13 -> 0 | K13: =IF(J13<$N$10,"tdk tuntas","tuntas") -> tdk tuntas | L13: =IF(J13<=39.9,"77",IF(J13<=59.9,"78",IF(J13<=69.9,"79",IF(J13<=74.9,"79",IF(J13<=78.9,"79",IF(J13<=78.9,"79",IF(J13>=78.9,J13," "))))))) -> 77 | M13: Hasil Analisa | Q13: =C13 -> Arif Perdana Putra | R13: =IF(I13<$N$10,"79","") -> 79 | T13: dan penyelesaiannya
A14: 7 | C14: =DATA!B16 -> Asifa Nariyati | I14: =SUM(D14:H14) -> 0 | J14: =I14 -> 0 | K14: =IF(J14<$N$10,"tdk tuntas","tuntas") -> tdk tuntas | L14: =IF(J14<=39.9,"77",IF(J14<=59.9,"78",IF(J14<=69.9,"79",IF(J14<=74.9,"79",IF(J14<=78.9,"79",IF(J14<=78.9,"79",IF(J14>=78.9,J14," "))))))) -> 77 | Q14: =C14 -> Asifa Nariyati | R14: =IF(I14<$N$10,"79","") -> 79 | S14: V | T14: Mengerjakan soal
A15: 8 | C15: =DATA!B17 -> Calvin Mandala Putra | I15: =SUM(D15:H15) -> 0 | J15: =I15 -> 0 | K15: =IF(J15<$N$10,"tdk tuntas","tuntas") -> tdk tuntas | L15: =IF(J15<=39.9,"77",IF(J15<=59.9,"78",IF(J15<=69.9,"79",IF(J15<=74.9,"79",IF(J15<=78.9,"79",IF(J15<=78.9,"79",IF(J15>=78.9,J15," "))))))) -> 77 | M15: a. Tuntas Klasikal | Q15: =C15 -> Calvin Mandala Putra | R15: =IF(I15<$N$10,"79","") -> 79 | T15: dengan bobot sama
A16: 9 | C16: =DATA!B18 -> Decha Rifqoh Alma Dhini | I16: =SUM(D16:H16) -> 0 | J16: =I16 -> 0 | K16: =IF(J16<$N$10,"tdk tuntas","tuntas") -> tdk tuntas | L16: =IF(J16<=39.9,"77",IF(J16<=59.9,"78",IF(J16<=69.9,"79",IF(J16<=74.9,"79",IF(J16<=78.9,"79",IF(J16<=78.9,"79",IF(J16>=78.9,J16," "))))))) -> 77 | Q16: =C16 -> Decha Rifqoh Alma Dhini | R16: =IF(I16<$N$10,"79","") -> 79
A17: 10 | C17: =DATA!B19 -> Fathir Hibatullah Harahap | I17: =SUM(D17:H17) -> 0 | J17: =I17 -> 0 | K17: =IF(J17<$N$10,"tdk tuntas","tuntas") -> tdk tuntas | L17: =IF(J17<=39.9,"77",IF(J17<=59.9,"78",IF(J17<=69.9,"79",IF(J17<=74.9,"79",IF(J17<=78.9,"79",IF(J17<=78.9,"79",IF(J17>=78.9,J17," "))))))) -> 77 | Q17: =C17 -> Fathir Hibatullah Harahap | R17: =IF(I17<$N$10,"85","") -> 85 | S17: PENGAYAAN
A18: 11 | C18: =DATA!B20 -> Gendhis Putri Ayreanti | I18: =SUM(D18:H18) -> 0 | J18: =I18 -> 0 | K18: =IF(J18<$N$10,"tdk tuntas","tuntas") -> tdk tuntas | L18: =IF(J18<=39.9,"77",IF(J18<=59.9,"78",IF(J18<=69.9,"79",IF(J18<=74.9,"79",IF(J18<=78.9,"79",IF(J18<=78.9,"79",IF(J18>=78.9,J18," "))))))) -> 77 | Q18: =C18 -> Gendhis Putri Ayreanti | R18: =IF(I18<$N$10,"85","") -> 85
A19: 12 | C19: =DATA!B21 -> Habibi Lazuardi | I19: =SUM(D19:H19) -> 0 | J19: =I19 -> 0 | K19: =IF(J19<$N$10,"tdk tuntas","tuntas") -> tdk tuntas | L19: =IF(J19<=39.9,"77",IF(J19<=59.9,"78",IF(J19<=69.9,"79",IF(J19<=74.9,"79",IF(J19<=78.9,"79",IF(J19<=78.9,"79",IF(J19>=78.9,J19," "))))))) -> 77 | M19: Banyak siswa seluruhnya | N19: =K46 -> 34 | Q19: =C19 -> Habibi Lazuardi | R19: =IF(I19<$N$10,"85","") -> 85 | S19: V | T19: Menyelesaikan soal soal
A20: 13 | C20: =DATA!B22 -> Herina Sasha Rasati | I20: =SUM(D20:H20) -> 0 | J20: =I20 -> 0 | K20: =IF(J20<$N$10,"tdk tuntas","tuntas") -> tdk tuntas | L20: =IF(J20<=39.9,"77",IF(J20<=59.9,"78",IF(J20<=69.9,"79",IF(J20<=74.9,"79",IF(J20<=78.9,"79",IF(J20<=78.9,"79",IF(J20>=78.9,J20," "))))))) -> 77 | M20: Banyak siswa yg tuntas | N20: =K44 -> 0 | Q20: =C20 -> Herina Sasha Rasati | R20: =IF(I20<$N$10,"85","") -> 85 | T20: pengayaan
A21: 14 | C21: =DATA!B23 -> Ivan Adi Saputra | I21: =SUM(D21:H21) -> 0 | J21: =I21 -> 0 | K21: =IF(J21<$N$10,"tdk tuntas","tuntas") -> tdk tuntas | L21: =IF(J21<=39.9,"77",IF(J21<=59.9,"78",IF(J21<=69.9,"79",IF(J21<=74.9,"79",IF(J21<=78.9,"79",IF(J21<=78.9,"79",IF(J21>=78.9,J21," "))))))) -> 77 | M21: Prosentase ketuntasan | N21: =N20/N19*100 -> 0 | O21: % | Q21: =C21 -> Ivan Adi Saputra | R21: =IF(I21<$N$10,"85","") -> 85 | T21: Mempelajari materi / KD
A22: 15 | C22: =DATA!B24 -> Ivander Veda Ardyanta | I22: =SUM(D22:H22) -> 0 | J22: =I22 -> 0 | K22: =IF(J22<$N$10,"tdk tuntas","tuntas") -> tdk tuntas | L22: =IF(J22<=39.9,"77",IF(J22<=59.9,"78",IF(J22<=69.9,"79",IF(J22<=74.9,"79",IF(J22<=78.9,"79",IF(J22<=78.9,"79",IF(J22>=78.9,J22," "))))))) -> 77 | Q22: =C22 -> Ivander Veda Ardyanta | R22: =IF(I22<$N$10,"85","") -> 85 | T22: berikutnya
A23: 16 | C23: =DATA!B25 -> Keysa Lutfi Yana Putri | I23: =SUM(D23:H23) -> 0 | J23: =I23 -> 0 | K23: =IF(J23<$N$10,"tdk tuntas","tuntas") -> tdk tuntas | L23: =IF(J23<=39.9,"77",IF(J23<=59.9,"78",IF(J23<=69.9,"79",IF(J23<=74.9,"79",IF(J23<=78.9,"79",IF(J23<=78.9,"79",IF(J23>=78.9,J23," "))))))) -> 77 | M23: b. Tuntas Individu | Q23: =C23 -> Keysa Lutfi Yana Putri | R23: =IF(I23<$N$10,"84","") -> 84
A24: 17 | C24: =DATA!B26 -> Khanaya Putri Emeyliana | I24: =SUM(D24:H24) -> 0 | J24: =I24 -> 0 | K24: =IF(J24<$N$10,"tdk tuntas","tuntas") -> tdk tuntas | L24: =IF(J24<=39.9,"77",IF(J24<=59.9,"78",IF(J24<=69.9,"79",IF(J24<=74.9,"79",IF(J24<=78.9,"79",IF(J24<=78.9,"79",IF(J24>=78.9,J24," "))))))) -> 77 | Q24: =C24 -> Khanaya Putri Emeyliana | R24: =IF(I24<$N$10,"82","") -> 82 | T24: Guru Mata Pelajaran
A25: 18 | C25: =DATA!B27 -> Khoirul Rodzikin | I25: =SUM(D25:H25) -> 0 | J25: =I25 -> 0 | K25: =IF(J25<$N$10,"tdk tuntas","tuntas") -> tdk tuntas | L25: =IF(J25<=39.9,"77",IF(J25<=59.9,"78",IF(J25<=69.9,"79",IF(J25<=74.9,"79",IF(J25<=78.9,"79",IF(J25<=78.9,"79",IF(J25>=78.9,J25," "))))))) -> 77 | Q25: =C25 -> Khoirul Rodzikin | R25: =IF(I25<$N$10,"82","") -> 82
A26: 19 | C26: =DATA!B28 -> Livia Mozavina | I26: =SUM(D26:H26) -> 0 | J26: =I26 -> 0 | K26: =IF(J26<$N$10,"tdk tuntas","tuntas") -> tdk tuntas | L26: =IF(J26<=39.9,"77",IF(J26<=59.9,"78",IF(J26<=69.9,"79",IF(J26<=74.9,"79",IF(J26<=78.9,"79",IF(J26<=78.9,"79",IF(J26>=78.9,J26," "))))))) -> 77 | Q26: =C26 -> Livia Mozavina | R26: =IF(I26<$N$10,"82","") -> 82
A27: 20 | C27: =DATA!B29 -> Milatul Ulya Azzahra | I27: =SUM(D27:H27) -> 0 | J27: =I27 -> 0 | K27: =IF(J27<$N$10,"tdk tuntas","tuntas") -> tdk tuntas | L27: =IF(J27<=39.9,"77",IF(J27<=59.9,"78",IF(J27<=69.9,"79",IF(J27<=74.9,"79",IF(J27<=78.9,"79",IF(J27<=78.9,"79",IF(J27>=78.9,J27," "))))))) -> 77 | M27: Juml nilai perolehan sw | N27: =I44 -> 0 | Q27: =C27 -> Milatul Ulya Azzahra | R27: =IF(I27<$N$10,"82","") -> 82
A28: 21 | C28: =DATA!B30 -> Muhammad Arif Pratama | I28: =SUM(D28:H28) -> 0 | J28: =I28 -> 0 | K28: =IF(J28<$N$10,"tdk tuntas","tuntas") -> tdk tuntas | L28: =IF(J28<=39.9,"77",IF(J28<=59.9,"78",IF(J28<=69.9,"79",IF(J28<=74.9,"79",IF(J28<=78.9,"79",IF(J28<=78.9,"79",IF(J28>=78.9,J28," "))))))) -> 77 | M28: Juml nili seluruhnya | N28: =I45 -> 3400 | Q28: =C28 -> Muhammad Arif Pratama | R28: =IF(I28<$N$10,"82","") -> 82 | T28: =DATA!B3 -> KASMIN, S.Pd
A29: 22 | C29: =DATA!B31 -> Muhammad Fahri Khoirudin | I29: =SUM(D29:H29) -> 0 | J29: =I29 -> 0 | K29: =IF(J29<$N$10,"tdk tuntas","tuntas") -> tdk tuntas | L29: =IF(J29<=39.9,"77",IF(J29<=59.9,"78",IF(J29<=69.9,"79",IF(J29<=74.9,"79",IF(J29<=78.9,"79",IF(J29<=78.9,"79",IF(J29>=78.9,J29," "))))))) -> 77 | M29: Prosentase ketuntasan | N29: =N27/N28*100 -> 0 | O29: % | Q29: =C29 -> Muhammad Fahri Khoirudin | R29: =IF(I29<$N$10,"82","") -> 82 | T29: =DATA!B4 -> NIP : 196609141990031007
A30: 23 | C30: =DATA!B32 -> Muhammad Rakha Razansyah | I30: =SUM(D30:H30) -> 0 | J30: =I30 -> 0 | K30: =IF(J30<$N$10,"tdk tuntas","tuntas") -> tdk tuntas | L30: =IF(J30<=39.9,"77",IF(J30<=59.9,"78",IF(J30<=69.9,"79",IF(J30<=74.9,"79",IF(J30<=78.9,"79",IF(J30<=78.9,"79",IF(J30>=78.9,J30," "))))))) -> 77 | Q30: =C30 -> Muhammad Rakha Razansyah | R30: =IF(I30<$N$10,"82","") -> 82
A31: 24 | C31: =DATA!B33 -> Mutiara Dewi Khusna | I31: =SUM(D31:H31) -> 0 | J31: =I31 -> 0 | K31: =IF(J31<$N$10,"tdk tuntas","tuntas") -> tdk tuntas | L31: =IF(J31<=39.9,"77",IF(J31<=59.9,"78",IF(J31<=69.9,"79",IF(J31<=74.9,"79",IF(J31<=78.9,"79",IF(J31<=78.9,"79",IF(J31>=78.9,J31," "))))))) -> 77 | Q31: =C31 -> Mutiara Dewi Khusna | R31: =IF(I31<$N$10,"79","") -> 79 | T31: Kepala Sekolah
A32: 25 | C32: =DATA!B34 -> Qeysya Nabila Maharani | I32: =SUM(D32:H32) -> 0 | J32: =I32 -> 0 | K32: =IF(J32<$N$10,"tdk tuntas","tuntas") -> tdk tuntas | L32: =IF(J32<=39.9,"77",IF(J32<=59.9,"78",IF(J32<=69.9,"79",IF(J32<=74.9,"79",IF(J32<=78.9,"79",IF(J32<=78.9,"79",IF(J32>=78.9,J32," "))))))) -> 77 | M32: Daya serap klasikal : | Q32: =C32 -> Qeysya Nabila Maharani | R32: =IF(I32<$N$10,"79","") -> 79
A33: 26 | C33: =DATA!B35 -> Raihan Akbar Ramadhan | I33: =SUM(D33:H33) -> 0 | J33: =I33 -> 0 | K33: =IF(J33<$N$10,"tdk tuntas","tuntas") -> tdk tuntas | L33: =IF(J33<=39.9,"77",IF(J33<=59.9,"78",IF(J33<=69.9,"79",IF(J33<=74.9,"79",IF(J33<=78.9,"79",IF(J33<=78.9,"79",IF(J33>=78.9,J33," "))))))) -> 77 | M33: Suatu kls dinytkn tuntas | Q33: =C33 -> Raihan Akbar Ramadhan | R33: =IF(I33<$N$10,"79","") -> 79
